Workbook

Sheet Inputs
A1: TGP Fund One Model Inputs
A2: Built by Reif Tauati · 4176197004 · reif@thegoodproject.net
A4: Core Assumptions
A5: Max Fund Size ($B) | B5: 1 | C5: Investor-facing guidance
A6: Capital Calls On (1=yes, 0=no) | B6: 1 | C6: Max Fund Size is the hard ceiling on total LP capital called.
A7: Hardcore Mode (1=yes, 0=no) | B7: 0 | C7: Capital Calls On means equity is called only when needed. Hardcore Mode forces fully funded upfront deployment with zero idle cash.
A8: Loan Size ($M) | B8: 25 | C8: Borrower Rate is what the developer pays. Fund Take is what the fund retains after origination partners are paid.
A9: Base Deals / Month | B9: 3 | C9: Debt / Equity of 0.25 means $0.25 of debt for each $1.00 of LP equity.
A10: Loan Term (months) | B10: 18
A11: Debt / Equity | B11: 0
A12: Borrower Rate | B12: 0.25
A13: Fund Take | B13: 0.18
A14: Cost of Debt | B14: 0.08
A15: Target IRR | B15: 0.15
A16: View Months | B16: 120
A18: Derived
A19: Just-in-Time Calls Active | B19: =IF(B7=1,0,B6)
A20: Total Lending Multiple | B20: =1+B11
A21: Shares Outstanding | B21: =B5*1000000000/1000
A22: Initial LP Call ($) | B22: =IF(B19=1,0,B5*1000000000)

Sheet Summary
A1: Fund One Excel Model Summary
A2: Contact Reif Tauati · 4176197004 · reif@thegoodproject.net
A4: Scenario Output
A5: Projected IRR | B5: =Monthly_Model!AI127 | C5: How to use this workbook
A6: Year 10 NAV / Share | B6: =Monthly_Model!AC127 | C6: Yellow cells on Inputs are editable assumptions.
A7: Lowest Cash | B7: =MIN(Monthly_Model!$Z$7:$Z$127) | C7: Green cells are modeled outputs.
A8: Peak LP Capital Out | B8: =MAX(Monthly_Model!$AD$7:$AD$127) | C8: Monthly_Model contains the full 10-year monthly build with formulas.
A9: Peak Debt | B9: =MAX(Monthly_Model!$AE$7:$AE$127) | C9: Hardcore Mode redeploys all available cash immediately and disables just-in-time capital calling.
A10: Peak New Loan Volume / Month | B10: =MAX(Monthly_Model!$V$8:$V$127)
A11: Peak Loans / Month | B11: =MAX(Monthly_Model!$AG$8:$AG$127)
A12: Total LP Called | B12: =MAX(Monthly_Model!$AH$7:$AH$127)
A13: Total Loans Originated | B13: =SUM(Monthly_Model!$AG$8:$AG$127)
A14: Target vs Projected Gap | B14: =Monthly_Model!AI127-Inputs!B15

Sheet Monthly_Model
A1: 10-Year Monthly Projection
A2: Formulas trace the current /model logic. Edit Inputs and Excel will recalculate.
A6: Month | B6: Label | C6: Opening Cash | D6: Opening NAV | E6: Carry Interest | F6: Carry Principal | G6: Active Eq Open | H6: Active Debt Open | I6: Carry Debt Cost | J6: Pre-Deploy Cash | K6: Remaining Callable | L6: Deployable Eq Cap | M6: Loan Size | N6: Base Deals | O6: Pipeline Scale | P6: Ramp | Q6: Scaled Deals | R6: Desired Orig Vol | S6: Desired Eq Deploy | T6: Actual Eq Deploy | U6: LP Call | V6: Actual Orig Vol | W6: Debt Deploy | X6: Immediate Interest | Y6: Immediate Debt Cost | Z6: Ending Cash | AA6: Ending NAV | AB6: Target NAV | AC6: NAV / Share | AD6: Active Eq Close | AE6: Active Debt Close | AF6: Loans Outstanding | AG6: New Loans / Mo | AH6: Cumulative LP Called | AI6: IRR To Date | AJ6: LP Flow Helper
A7: 0 | B7: Start | C7: =Inputs!B22 | D7: =Inputs!B22 | E7: 0 | F7: 0 | G7: 0 | H7: 0 | I7: 0 | J7: 0 | K7: 0 | L7: 0 | M7: 0 | N7: 0 | O7: 0 | P7: 0 | Q7: 0 | R7: 0 | S7: 0 | T7: 0 | U7: 0 | V7: 0 | W7: 0 | X7: 0 | Y7: 0 | Z7: =C7 | AA7: =D7 | AB7: =Inputs!B22 | AC7: =IF(Inputs!B21>0,AA7/Inputs!B21,0) | AD7: 0 | AE7: 0 | AF7: 0 | AG7: =0 | AH7: =Inputs!B22 | AI7: 0 | AJ7: 0
A8: =A7+1 | B8: Month 1 | C8: =Z7 | D8: =AA7 | E8: =IF(A8<=12,0,INDEX($V$8:$V$127,A8-12)*Inputs!B13*MAX(0,Inputs!B10-12)/12) | F8: =IF(A8<=Inputs!B10,0,INDEX($T$8:$T$127,A8-Inputs!B10)) | G8: =AD7-F8 | H8: =AE7-IF(A8<=Inputs!B10,0,INDEX($W$8:$W$127,A8-Inputs!B10)) | I8: =H8*Inputs!B14/12 | J8: =C8+E8+F8-I8 | K8: =IF(Inputs!B19=1,MAX(0,Inputs!B5*1000000000-AH7),0) | L8: =MAX(0,J8+K8) | M8: =Inputs!B8*1000000 | N8: =Inputs!B9 | O8: =MAX(1,SQRT(L8/MAX(M8*MAX(N8,0.01)/(1+Inputs!B11),1))) | P8: =MIN(1,A8/12) | Q8: =IF(Inputs!B7=1,MAX(N8,L8*(1+Inputs!B11)/MAX(M8,1)),N8+(N8*O8-N8)*P8) | R8: =IF(Inputs!B7=1,L8*(1+Inputs!B11),M8*Q8) | S8: =R8/(1+Inputs!B11) | T8: =IF(Inputs!B7=1,L8,MIN(S8,L8)) | U8: =IF(Inputs!B19=1,MAX(0,T8-J8),0) | V8: =T8*(1+Inputs!B11) | W8: =V8-T8 | X8: =V8*Inputs!B13*MIN(12,Inputs!B10)/12 | Y8: =W8*Inputs!B14/12 | Z8: =J8+U8-T8+X8-Y8 | AA8: =D8+E8-I8+U8+X8-Y8 | AB8: =IF(U8>0,AB7*(1+Inputs!B15/12)+U8,AB7*(1+Inputs!B15/12)) | AC8: =IF(Inputs!B21>0,AA8/Inputs!B21,0) | AD8: =G8+T8 | AE8: =H8+W8 | AF8: =AD8+AE8 | AG8: =IF(M8>0,V8/M8,0) | AH8: =AH7+U8 | AI8: 0 | AJ8: =-U8
A9: =A8+1 | B9: Month 2 | C9: =Z8 | D9: =AA8 | E9: =IF(A9<=12,0,INDEX($V$8:$V$127,A9-12)*Inputs!B13*MAX(0,Inputs!B10-12)/12) | F9: =IF(A9<=Inputs!B10,0,INDEX($T$8:$T$127,A9-Inputs!B10)) | G9: =AD8-F9 | H9: =AE8-IF(A9<=Inputs!B10,0,INDEX($W$8:$W$127,A9-Inputs!B10)) | I9: =H9*Inputs!B14/12 | J9: =C9+E9+F9-I9 | K9: =IF(Inputs!B19=1,MAX(0,Inputs!B5*1000000000-AH8),0) | L9: =MAX(0,J9+K9) | M9: =Inputs!B8*1000000 | N9: =Inputs!B9 | O9: =MAX(1,SQRT(L9/MAX(M9*MAX(N9,0.01)/(1+Inputs!B11),1))) | P9: =MIN(1,A9/12) | Q9: =IF(Inputs!B7=1,MAX(N9,L9*(1+Inputs!B11)/MAX(M9,1)),N9+(N9*O9-N9)*P9) | R9: =IF(Inputs!B7=1,L9*(1+Inputs!B11),M9*Q9) | S9: =R9/(1+Inputs!B11) | T9: =IF(Inputs!B7=1,L9,MIN(S9,L9)) | U9: =IF(Inputs!B19=1,MAX(0,T9-J9),0) | V9: =T9*(1+Inputs!B11) | W9: =V9-T9 | X9: =V9*Inputs!B13*MIN(12,Inputs!B10)/12 | Y9: =W9*Inputs!B14/12 | Z9: =J9+U9-T9+X9-Y9 | AA9: =D9+E9-I9+U9+X9-Y9 | AB9: =IF(U9>0,AB8*(1+Inputs!B15/12)+U9,AB8*(1+Inputs!B15/12)) | AC9: =IF(Inputs!B21>0,AA9/Inputs!B21,0) | AD9: =G9+T9 | AE9: =H9+W9 | AF9: =AD9+AE9 | AG9: =IF(M9>0,V9/M9,0) | AH9: =AH8+U9 | AI9: =IFERROR((1+IRR(VSTACK($AJ$8:INDEX($AJ:$AJ,ROW()-1),-U9+AA9)))^12-1,0) | AJ9: =-U9
A10: =A9+1 | B10: Month 3 | C10: =Z9 | D10: =AA9 | E10: =IF(A10<=12,0,INDEX($V$8:$V$127,A10-12)*Inputs!B13*MAX(0,Inputs!B10-12)/12) | F10: =IF(A10<=Inputs!B10,0,INDEX($T$8:$T$127,A10-Inputs!B10)) | G10: =AD9-F10 | H10: =AE9-IF(A10<=Inputs!B10,0,INDEX($W$8:$W$127,A10-Inputs!B10)) | I10: =H10*Inputs!B14/12 | J10: =C10+E10+F10-I10 | K10: =IF(Inputs!B19=1,MAX(0,Inputs!B5*1000000000-AH9),0) | L10: =MAX(0,J10+K10) | M10: =Inputs!B8*1000000 | N10: =Inputs!B9 | O10: =MAX(1,SQRT(L10/MAX(M10*MAX(N10,0.01)/(1+Inputs!B11),1))) | P10: =MIN(1,A10/12) | Q10: =IF(Inputs!B7=1,MAX(N10,L10*(1+Inputs!B11)/MAX(M10,1)),N10+(N10*O10-N10)*P10) | R10: =IF(Inputs!B7=1,L10*(1+Inputs!B11),M10*Q10) | S10: =R10/(1+Inputs!B11) | T10: =IF(Inputs!B7=1,L10,MIN(S10,L10)) | U10: =IF(Inputs!B19=1,MAX(0,T10-J10),0) | V10: =T10*(1+Inputs!B11) | W10: =V10-T10 | X10: =V10*Inputs!B13*MIN(12,Inputs!B10)/12 | Y10: =W10*Inputs!B14/12 | Z10: =J10+U10-T10+X10-Y10 | AA10: =D10+E10-I10+U10+X10-Y10 | AB10: =IF(U10>0,AB9*(1+Inputs!B15/12)+U10,AB9*(1+Inputs!B15/12)) | AC10: =IF(Inputs!B21>0,AA10/Inputs!B21,0) | AD10: =G10+T10 | AE10: =H10+W10 | AF10: =AD10+AE10 | AG10: =IF(M10>0,V10/M10,0) | AH10: =AH9+U10 | AI10: =IFERROR((1+IRR(VSTACK($AJ$8:INDEX($AJ:$AJ,ROW()-1),-U10+AA10)))^12-1,0) | AJ10: =-U10
A11: =A10+1 | B11: Month 4 | C11: =Z10 | D11: =AA10 | E11: =IF(A11<=12,0,INDEX($V$8:$V$127,A11-12)*Inputs!B13*MAX(0,Inputs!B10-12)/12) | F11: =IF(A11<=Inputs!B10,0,INDEX($T$8:$T$127,A11-Inputs!B10)) | G11: =AD10-F11 | H11: =AE10-IF(A11<=Inputs!B10,0,INDEX($W$8:$W$127,A11-Inputs!B10)) | I11: =H11*Inputs!B14/12 | J11: =C11+E11+F11-I11 | K11: =IF(Inputs!B19=1,MAX(0,Inputs!B5*1000000000-AH10),0) | L11: =MAX(0,J11+K11) | M11: =Inputs!B8*1000000 | N11: =Inputs!B9 | O11: =MAX(1,SQRT(L11/MAX(M11*MAX(N11,0.01)/(1+Inputs!B11),1))) | P11: =MIN(1,A11/12) | Q11: =IF(Inputs!B7=1,MAX(N11,L11*(1+Inputs!B11)/MAX(M11,1)),N11+(N11*O11-N11)*P11) | R11: =IF(Inputs!B7=1,L11*(1+Inputs!B11),M11*Q11) | S11: =R11/(1+Inputs!B11) | T11: =IF(Inputs!B7=1,L11,MIN(S11,L11)) | U11: =IF(Inputs!B19=1,MAX(0,T11-J11),0) | V11: =T11*(1+Inputs!B11) | W11: =V11-T11 | X11: =V11*Inputs!B13*MIN(12,Inputs!B10)/12 | Y11: =W11*Inputs!B14/12 | Z11: =J11+U11-T11+X11-Y11 | AA11: =D11+E11-I11+U11+X11-Y11 | AB11: =IF(U11>0,AB10*(1+Inputs!B15/12)+U11,AB10*(1+Inputs!B15/12)) | AC11: =IF(Inputs!B21>0,AA11/Inputs!B21,0) | AD11: =G11+T11 | AE11: =H11+W11 | AF11: =AD11+AE11 | AG11: =IF(M11>0,V11/M11,0) | AH11: =AH10+U11 | AI11: =IFERROR((1+IRR(VSTACK($AJ$8:INDEX($AJ:$AJ,ROW()-1),-U11+AA11)))^12-1,0) | AJ11: =-U11
A12: =A11+1 | B12: Month 5 | C12: =Z11 | D12: =AA11 | E12: =IF(A12<=12,0,INDEX($V$8:$V$127,A12-12)*Inputs!B13*MAX(0,Inputs!B10-12)/12) | F12: =IF(A12<=Inputs!B10,0,INDEX($T$8:$T$127,A12-Inputs!B10)) | G12: =AD11-F12 | H12: =AE11-IF(A12<=Inputs!B10,0,INDEX($W$8:$W$127,A12-Inputs!B10)) | I12: =H12*Inputs!B14/12 | J12: =C12+E12+F12-I12 | K12: =IF(Inputs!B19=1,MAX(0,Inputs!B5*1000000000-AH11),0) | L12: =MAX(0,J12+K12) | M12: =Inputs!B8*1000000 | N12: =Inputs!B9 | O12: =MAX(1,SQRT(L12/MAX(M12*MAX(N12,0.01)/(1+Inputs!B11),1))) | P12: =MIN(1,A12/12) | Q12: =IF(Inputs!B7=1,MAX(N12,L12*(1+Inputs!B11)/MAX(M12,1)),N12+(N12*O12-N12)*P12) | R12: =IF(Inputs!B7=1,L12*(1+Inputs!B11),M12*Q12) | S12: =R12/(1+Inputs!B11) | T12: =IF(Inputs!B7=1,L12,MIN(S12,L12)) | U12: =IF(Inputs!B19=1,MAX(0,T12-J12),0) | V12: =T12*(1+Inputs!B11) | W12: =V12-T12 | X12: =V12*Inputs!B13*MIN(12,Inputs!B10)/12 | Y12: =W12*Inputs!B14/12 | Z12: =J12+U12-T12+X12-Y12 | AA12: =D12+E12-I12+U12+X12-Y12 | AB12: =IF(U12>0,AB11*(1+Inputs!B15/12)+U12,AB11*(1+Inputs!B15/12)) | AC12: =IF(Inputs!B21>0,AA12/Inputs!B21,0) | AD12: =G12+T12 | AE12: =H12+W12 | AF12: =AD12+AE12 | AG12: =IF(M12>0,V12/M12,0) | AH12: =AH11+U12 | AI12: =IFERROR((1+IRR(VSTACK($AJ$8:INDEX($AJ:$AJ,ROW()-1),-U12+AA12)))^12-1,0) | AJ12: =-U12
A13: =A12+1 | B13: Month 6 | C13: =Z12 | D13: =AA12 | E13: =IF(A13<=12,0,INDEX($V$8:$V$127,A13-12)*Inputs!B13*MAX(0,Inputs!B10-12)/12) | F13: =IF(A13<=Inputs!B10,0,INDEX($T$8:$T$127,A13-Inputs!B10)) | G13: =AD12-F13 | H13: =AE12-IF(A13<=Inputs!B10,0,INDEX($W$8:$W$127,A13-Inputs!B10)) | I13: =H13*Inputs!B14/12 | J13: =C13+E13+F13-I13 | K13: =IF(Inputs!B19=1,MAX(0,Inputs!B5*1000000000-AH12),0) | L13: =MAX(0,J13+K13) | M13: =Inputs!B8*1000000 | N13: =Inputs!B9 | O13: =MAX(1,SQRT(L13/MAX(M13*MAX(N13,0.01)/(1+Inputs!B11),1))) | P13: =MIN(1,A13/12) | Q13: =IF(Inputs!B7=1,MAX(N13,L13*(1+Inputs!B11)/MAX(M13,1)),N13+(N13*O13-N13)*P13) | R13: =IF(Inputs!B7=1,L13*(1+Inputs!B11),M13*Q13) | S13: =R13/(1+Inputs!B11) | T13: =IF(Inputs!B7=1,L13,MIN(S13,L13)) | U13: =IF(Inputs!B19=1,MAX(0,T13-J13),0) | V13: =T13*(1+Inputs!B11) | W13: =V13-T13 | X13: =V13*Inputs!B13*MIN(12,Inputs!B10)/12 | Y13: =W13*Inputs!B14/12 | Z13: =J13+U13-T13+X13-Y13 | AA13: =D13+E13-I13+U13+X13-Y13 | AB13: =IF(U13>0,AB12*(1+Inputs!B15/12)+U13,AB12*(1+Inputs!B15/12)) | AC13: =IF(Inputs!B21>0,AA13/Inputs!B21,0) | AD13: =G13+T13 | AE13: =H13+W13 | AF13: =AD13+AE13 | AG13: =IF(M13>0,V13/M13,0) | AH13: =AH12+U13 | AI13: =IFERROR((1+IRR(VSTACK($AJ$8:INDEX($AJ:$AJ,ROW()-1),-U13+AA13)))^12-1,0) | AJ13: =-U13
A14: =A13+1 | B14: Month 7 | C14: =Z13 | D14: =AA13 | E14: =IF(A14<=12,0,INDEX($V$8:$V$127,A14-12)*Inputs!B13*MAX(0,Inputs!B10-12)/12) | F14: =IF(A14<=Inputs!B10,0,INDEX($T$8:$T$127,A14-Inputs!B10)) | G14: =AD13-F14 | H14: =AE13-IF(A14<=Inputs!B10,0,INDEX($W$8:$W$127,A14-Inputs!B10)) | I14: =H14*Inputs!B14/12 | J14: =C14+E14+F14-I14 | K14: =IF(Inputs!B19=1,MAX(0,Inputs!B5*1000000000-AH13),0) | L14: =MAX(0,J14+K14) | M14: =Inputs!B8*1000000 | N14: =Inputs!B9 | O14: =MAX(1,SQRT(L14/MAX(M14*MAX(N14,0.01)/(1+Inputs!B11),1))) | P14: =MIN(1,A14/12) | Q14: =IF(Inputs!B7=1,MAX(N14,L14*(1+Inputs!B11)/MAX(M14,1)),N14+(N14*O14-N14)*P14) | R14: =IF(Inputs!B7=1,L14*(1+Inputs!B11),M14*Q14) | S14: =R14/(1+Inputs!B11) | T14: =IF(Inputs!B7=1,L14,MIN(S14,L14)) | U14: =IF(Inputs!B19=1,MAX(0,T14-J14),0) | V14: =T14*(1+Inputs!B11) | W14: =V14-T14 | X14: =V14*Inputs!B13*MIN(12,Inputs!B10)/12 | Y14: =W14*Inputs!B14/12 | Z14: =J14+U14-T14+X14-Y14 | AA14: =D14+E14-I14+U14+X14-Y14 | AB14: =IF(U14>0,AB13*(1+Inputs!B15/12)+U14,AB13*(1+Inputs!B15/12)) | AC14: =IF(Inputs!B21>0,AA14/Inputs!B21,0) | AD14: =G14+T14 | AE14: =H14+W14 | AF14: =AD14+AE14 | AG14: =IF(M14>0,V14/M14,0) | AH14: =AH13+U14 | AI14: =IFERROR((1+IRR(VSTACK($AJ$8:INDEX($AJ:$AJ,ROW()-1),-U14+AA14)))^12-1,0) | AJ14: =-U14
A15: =A14+1 | B15: Month 8 | C15: =Z14 | D15: =AA14 | E15: =IF(A15<=12,0,INDEX($V$8:$V$127,A15-12)*Inputs!B13*MAX(0,Inputs!B10-12)/12) | F15: =IF(A15<=Inputs!B10,0,INDEX($T$8:$T$127,A15-Inputs!B10)) | G15: =AD14-F15 | H15: =AE14-IF(A15<=Inputs!B10,0,INDEX($W$8:$W$127,A15-Inputs!B10)) | I15: =H15*Inputs!B14/12 | J15: =C15+E15+F15-I15 | K15: =IF(Inputs!B19=1,MAX(0,Inputs!B5*1000000000-AH14),0) | L15: =MAX(0,J15+K15) | M15: =Inputs!B8*1000000 | N15: =Inputs!B9 | O15: =MAX(1,SQRT(L15/MAX(M15*MAX(N15,0.01)/(1+Inputs!B11),1))) | P15: =MIN(1,A15/12) | Q15: =IF(Inputs!B7=1,MAX(N15,L15*(1+Inputs!B11)/MAX(M15,1)),N15+(N15*O15-N15)*P15) | R15: =IF(Inputs!B7=1,L15*(1+Inputs!B11),M15*Q15) | S15: =R15/(1+Inputs!B11) | T15: =IF(Inputs!B7=1,L15,MIN(S15,L15)) | U15: =IF(Inputs!B19=1,MAX(0,T15-J15),0) | V15: =T15*(1+Inputs!B11) | W15: =V15-T15 | X15: =V15*Inputs!B13*MIN(12,Inputs!B10)/12 | Y15: =W15*Inputs!B14/12 | Z15: =J15+U15-T15+X15-Y15 | AA15: =D15+E15-I15+U15+X15-Y15 | AB15: =IF(U15>0,AB14*(1+Inputs!B15/12)+U15,AB14*(1+Inputs!B15/12)) | AC15: =IF(Inputs!B21>0,AA15/Inputs!B21,0) | AD15: =G15+T15 | AE15: =H15+W15 | AF15: =AD15+AE15 | AG15: =IF(M15>0,V15/M15,0) | AH15: =AH14+U15 | AI15: =IFERROR((1+IRR(VSTACK($AJ$8:INDEX($AJ:$AJ,ROW()-1),-U15+AA15)))^12-1,0) | AJ15: =-U15
A16: =A15+1 | B16: Month 9 | C16: =Z15 | D16: =AA15 | E16: =IF(A16<=12,0,INDEX($V$8:$V$127,A16-12)*Inputs!B13*MAX(0,Inputs!B10-12)/12) | F16: =IF(A16<=Inputs!B10,0,INDEX($T$8:$T$127,A16-Inputs!B10)) | G16: =AD15-F16 | H16: =AE15-IF(A16<=Inputs!B10,0,INDEX($W$8:$W$127,A16-Inputs!B10)) | I16: =H16*Inputs!B14/12 | J16: =C16+E16+F16-I16 | K16: =IF(Inputs!B19=1,MAX(0,Inputs!B5*1000000000-AH15),0) | L16: =MAX(0,J16+K16) | M16: =Inputs!B8*1000000 | N16: =Inputs!B9 | O16: =MAX(1,SQRT(L16/MAX(M16*MAX(N16,0.01)/(1+Inputs!B11),1))) | P16: =MIN(1,A16/12) | Q16: =IF(Inputs!B7=1,MAX(N16,L16*(1+Inputs!B11)/MAX(M16,1)),N16+(N16*O16-N16)*P16) | R16: =IF(Inputs!B7=1,L16*(1+Inputs!B11),M16*Q16) | S16: =R16/(1+Inputs!B11) | T16: =IF(Inputs!B7=1,L16,MIN(S16,L16)) | U16: =IF(Inputs!B19=1,MAX(0,T16-J16),0) | V16: =T16*(1+Inputs!B11) | W16: =V16-T16 | X16: =V16*Inputs!B13*MIN(12,Inputs!B10)/12 | Y16: =W16*Inputs!B14/12 | Z16: =J16+U16-T16+X16-Y16 | AA16: =D16+E16-I16+U16+X16-Y16 | AB16: =IF(U16>0,AB15*(1+Inputs!B15/12)+U16,AB15*(1+Inputs!B15/12)) | AC16: =IF(Inputs!B21>0,AA16/Inputs!B21,0) | AD16: =G16+T16 | AE16: =H16+W16 | AF16: =AD16+AE16 | AG16: =IF(M16>0,V16/M16,0) | AH16: =AH15+U16 | AI16: =IFERROR((1+IRR(VSTACK($AJ$8:INDEX($AJ:$AJ,ROW()-1),-U16+AA16)))^12-1,0) | AJ16: =-U16
A17: =A16+1 | B17: Month 10 | C17: =Z16 | D17: =AA16 | E17: =IF(A17<=12,0,INDEX($V$8:$V$127,A17-12)*Inputs!B13*MAX(0,Inputs!B10-12)/12) | F17: =IF(A17<=Inputs!B10,0,INDEX($T$8:$T$127,A17-Inputs!B10)) | G17: =AD16-F17 | H17: =AE16-IF(A17<=Inputs!B10,0,INDEX($W$8:$W$127,A17-Inputs!B10)) | I17: =H17*Inputs!B14/12 | J17: =C17+E17+F17-I17 | K17: =IF(Inputs!B19=1,MAX(0,Inputs!B5*1000000000-AH16),0) | L17: =MAX(0,J17+K17) | M17: =Inputs!B8*1000000 | N17: =Inputs!B9 | O17: =MAX(1,SQRT(L17/MAX(M17*MAX(N17,0.01)/(1+Inputs!B11),1))) | P17: =MIN(1,A17/12) | Q17: =IF(Inputs!B7=1,MAX(N17,L17*(1+Inputs!B11)/MAX(M17,1)),N17+(N17*O17-N17)*P17) | R17: =IF(Inputs!B7=1,L17*(1+Inputs!B11),M17*Q17) | S17: =R17/(1+Inputs!B11) | T17: =IF(Inputs!B7=1,L17,MIN(S17,L17)) | U17: =IF(Inputs!B19=1,MAX(0,T17-J17),0) | V17: =T17*(1+Inputs!B11) | W17: =V17-T17 | X17: =V17*Inputs!B13*MIN(12,Inputs!B10)/12 | Y17: =W17*Inputs!B14/12 | Z17: =J17+U17-T17+X17-Y17 | AA17: =D17+E17-I17+U17+X17-Y17 | AB17: =IF(U17>0,AB16*(1+Inputs!B15/12)+U17,AB16*(1+Inputs!B15/12)) | AC17: =IF(Inputs!B21>0,AA17/Inputs!B21,0) | AD17: =G17+T17 | AE17: =H17+W17 | AF17: =AD17+AE17 | AG17: =IF(M17>0,V17/M17,0) | AH17: =AH16+U17 | AI17: =IFERROR((1+IRR(VSTACK($AJ$8:INDEX($AJ:$AJ,ROW()-1),-U17+AA17)))^12-1,0) | AJ17: =-U17
A18: =A17+1 | B18: Month 11 | C18: =Z17 | D18: =AA17 | E18: =IF(A18<=12,0,INDEX($V$8:$V$127,A18-12)*Inputs!B13*MAX(0,Inputs!B10-12)/12) | F18: =IF(A18<=Inputs!B10,0,INDEX($T$8:$T$127,A18-Inputs!B10)) | G18: =AD17-F18 | H18: =AE17-IF(A18<=Inputs!B10,0,INDEX($W$8:$W$127,A18-Inputs!B10)) | I18: =H18*Inputs!B14/12 | J18: =C18+E18+F18-I18 | K18: =IF(Inputs!B19=1,MAX(0,Inputs!B5*1000000000-AH17),0) | L18: =MAX(0,J18+K18) | M18: =Inputs!B8*1000000 | N18: =Inputs!B9 | O18: =MAX(1,SQRT(L18/MAX(M18*MAX(N18,0.01)/(1+Inputs!B11),1))) | P18: =MIN(1,A18/12) | Q18: =IF(Inputs!B7=1,MAX(N18,L18*(1+Inputs!B11)/MAX(M18,1)),N18+(N18*O18-N18)*P18) | R18: =IF(Inputs!B7=1,L18*(1+Inputs!B11),M18*Q18) | S18: =R18/(1+Inputs!B11) | T18: =IF(Inputs!B7=1,L18,MIN(S18,L18)) | U18: =IF(Inputs!B19=1,MAX(0,T18-J18),0) | V18: =T18*(1+Inputs!B11) | W18: =V18-T18 | X18: =V18*Inputs!B13*MIN(12,Inputs!B10)/12 | Y18: =W18*Inputs!B14/12 | Z18: =J18+U18-T18+X18-Y18 | AA18: =D18+E18-I18+U18+X18-Y18 | AB18: =IF(U18>0,AB17*(1+Inputs!B15/12)+U18,AB17*(1+Inputs!B15/12)) | AC18: =IF(Inputs!B21>0,AA18/Inputs!B21,0) | AD18: =G18+T18 | AE18: =H18+W18 | AF18: =AD18+AE18 | AG18: =IF(M18>0,V18/M18,0) | AH18: =AH17+U18 | AI18: =IFERROR((1+IRR(VSTACK($AJ$8:INDEX($AJ:$AJ,ROW()-1),-U18+AA18)))^12-1,0) | AJ18: =-U18
A19: =A18+1 | B19: Month 12 | C19: =Z18 | D19: =AA18 | E19: =IF(A19<=12,0,INDEX($V$8:$V$127,A19-12)*Inputs!B13*MAX(0,Inputs!B10-12)/12) | F19: =IF(A19<=Inputs!B10,0,INDEX($T$8:$T$127,A19-Inputs!B10)) | G19: =AD18-F19 | H19: =AE18-IF(A19<=Inputs!B10,0,INDEX($W$8:$W$127,A19-Inputs!B10)) | I19: =H19*Inputs!B14/12 | J19: =C19+E19+F19-I19 | K19: =IF(Inputs!B19=1,MAX(0,Inputs!B5*1000000000-AH18),0) | L19: =MAX(0,J19+K19) | M19: =Inputs!B8*1000000 | N19: =Inputs!B9 | O19: =MAX(1,SQRT(L19/MAX(M19*MAX(N19,0.01)/(1+Inputs!B11),1))) | P19: =MIN(1,A19/12) | Q19: =IF(Inputs!B7=1,MAX(N19,L19*(1+Inputs!B11)/MAX(M19,1)),N19+(N19*O19-N19)*P19) | R19: =IF(Inputs!B7=1,L19*(1+Inputs!B11),M19*Q19) | S19: =R19/(1+Inputs!B11) | T19: =IF(Inputs!B7=1,L19,MIN(S19,L19)) | U19: =IF(Inputs!B19=1,MAX(0,T19-J19),0) | V19: =T19*(1+Inputs!B11) | W19: =V19-T19 | X19: =V19*Inputs!B13*MIN(12,Inputs!B10)/12 | Y19: =W19*Inputs!B14/12 | Z19: =J19+U19-T19+X19-Y19 | AA19: =D19+E19-I19+U19+X19-Y19 | AB19: =IF(U19>0,AB18*(1+Inputs!B15/12)+U19,AB18*(1+Inputs!B15/12)) | AC19: =IF(Inputs!B21>0,AA19/Inputs!B21,0) | AD19: =G19+T19 | AE19: =H19+W19 | AF19: =AD19+AE19 | AG19: =IF(M19>0,V19/M19,0) | AH19: =AH18+U19 | AI19: =IFERROR((1+IRR(VSTACK($AJ$8:INDEX($AJ:$AJ,ROW()-1),-U19+AA19)))^12-1,0) | AJ19: =-U19
A20: =A19+1 | B20: Month 13 | C20: =Z19 | D20: =AA19 | E20: =IF(A20<=12,0,INDEX($V$8:$V$127,A20-12)*Inputs!B13*MAX(0,Inputs!B10-12)/12) | F20: =IF(A20<=Inputs!B10,0,INDEX($T$8:$T$127,A20-Inputs!B10)) | G20: =AD19-F20 | H20: =AE19-IF(A20<=Inputs!B10,0,INDEX($W$8:$W$127,A20-Inputs!B10)) | I20: =H20*Inputs!B14/12 | J20: =C20+E20+F20-I20 | K20: =IF(Inputs!B19=1,MAX(0,Inputs!B5*1000000000-AH19),0) | L20: =MAX(0,J20+K20) | M20: =Inputs!B8*1000000 | N20: =Inputs!B9 | O20: =MAX(1,SQRT(L20/MAX(M20*MAX(N20,0.01)/(1+Inputs!B11),1))) | P20: =MIN(1,A20/12) | Q20: =IF(Inputs!B7=1,MAX(N20,L20*(1+Inputs!B11)/MAX(M20,1)),N20+(N20*O20-N20)*P20) | R20: =IF(Inputs!B7=1,L20*(1+Inputs!B11),M20*Q20) | S20: =R20/(1+Inputs!B11) | T20: =IF(Inputs!B7=1,L20,MIN(S20,L20)) | U20: =IF(Inputs!B19=1,MAX(0,T20-J20),0) | V20: =T20*(1+Inputs!B11) | W20: =V20-T20 | X20: =V20*Inputs!B13*MIN(12,Inputs!B10)/12 | Y20: =W20*Inputs!B14/12 | Z20: =J20+U20-T20+X20-Y20 | AA20: =D20+E20-I20+U20+X20-Y20 | AB20: =IF(U20>0,AB19*(1+Inputs!B15/12)+U20,AB19*(1+Inputs!B15/12)) | AC20: =IF(Inputs!B21>0,AA20/Inputs!B21,0) | AD20: =G20+T20 | AE20: =H20+W20 | AF20: =AD20+AE20 | AG20: =IF(M20>0,V20/M20,0) | AH20: =AH19+U20 | AI20: =IFERROR((1+IRR(VSTACK($AJ$8:INDEX($AJ:$AJ,ROW()-1),-U20+AA20)))^12-1,0) | AJ20: =-U20
A21: =A20+1 | B21: Month 14 | C21: =Z20 | D21: =AA20 | E21: =IF(A21<=12,0,INDEX($V$8:$V$127,A21-12)*Inputs!B13*MAX(0,Inputs!B10-12)/12) | F21: =IF(A21<=Inputs!B10,0,INDEX($T$8:$T$127,A21-Inputs!B10)) | G21: =AD20-F21 | H21: =AE20-IF(A21<=Inputs!B10,0,INDEX($W$8:$W$127,A21-Inputs!B10)) | I21: =H21*Inputs!B14/12 | J21: =C21+E21+F21-I21 | K21: =IF(Inputs!B19=1,MAX(0,Inputs!B5*1000000000-AH20),0) | L21: =MAX(0,J21+K21) | M21: =Inputs!B8*1000000 | N21: =Inputs!B9 | O21: =MAX(1,SQRT(L21/MAX(M21*MAX(N21,0.01)/(1+Inputs!B11),1))) | P21: =MIN(1,A21/12) | Q21: =IF(Inputs!B7=1,MAX(N21,L21*(1+Inputs!B11)/MAX(M21,1)),N21+(N21*O21-N21)*P21) | R21: =IF(Inputs!B7=1,L21*(1+Inputs!B11),M21*Q21) | S21: =R21/(1+Inputs!B11) | T21: =IF(Inputs!B7=1,L21,MIN(S21,L21)) | U21: =IF(Inputs!B19=1,MAX(0,T21-J21),0) | V21: =T21*(1+Inputs!B11) | W21: =V21-T21 | X21: =V21*Inputs!B13*MIN(12,Inputs!B10)/12 | Y21: =W21*Inputs!B14/12 | Z21: =J21+U21-T21+X21-Y21 | AA21: =D21+E21-I21+U21+X21-Y21 | AB21: =IF(U21>0,AB20*(1+Inputs!B15/12)+U21,AB20*(1+Inputs!B15/12)) | AC21: =IF(Inputs!B21>0,AA21/Inputs!B21,0) | AD21: =G21+T21 | AE21: =H21+W21 | AF21: =AD21+AE21 | AG21: =IF(M21>0,V21/M21,0) | AH21: =AH20+U21 | AI21: =IFERROR((1+IRR(VSTACK($AJ$8:INDEX($AJ:$AJ,ROW()-1),-U21+AA21)))^12-1,0) | AJ21: =-U21
A22: =A21+1 | B22: Month 15 | C22: =Z21 | D22: =AA21 | E22: =IF(A22<=12,0,INDEX($V$8:$V$127,A22-12)*Inputs!B13*MAX(0,Inputs!B10-12)/12) | F22: =IF(A22<=Inputs!B10,0,INDEX($T$8:$T$127,A22-Inputs!B10)) | G22: =AD21-F22 | H22: =AE21-IF(A22<=Inputs!B10,0,INDEX($W$8:$W$127,A22-Inputs!B10)) | I22: =H22*Inputs!B14/12 | J22: =C22+E22+F22-I22 | K22: =IF(Inputs!B19=1,MAX(0,Inputs!B5*1000000000-AH21),0) | L22: =MAX(0,J22+K22) | M22: =Inputs!B8*1000000 | N22: =Inputs!B9 | O22: =MAX(1,SQRT(L22/MAX(M22*MAX(N22,0.01)/(1+Inputs!B11),1))) | P22: =MIN(1,A22/12) | Q22: =IF(Inputs!B7=1,MAX(N22,L22*(1+Inputs!B11)/MAX(M22,1)),N22+(N22*O22-N22)*P22) | R22: =IF(Inputs!B7=1,L22*(1+Inputs!B11),M22*Q22) | S22: =R22/(1+Inputs!B11) | T22: =IF(Inputs!B7=1,L22,MIN(S22,L22)) | U22: =IF(Inputs!B19=1,MAX(0,T22-J22),0) | V22: =T22*(1+Inputs!B11) | W22: =V22-T22 | X22: =V22*Inputs!B13*MIN(12,Inputs!B10)/12 | Y22: =W22*Inputs!B14/12 | Z22: =J22+U22-T22+X22-Y22 | AA22: =D22+E22-I22+U22+X22-Y22 | AB22: =IF(U22>0,AB21*(1+Inputs!B15/12)+U22,AB21*(1+Inputs!B15/12)) | AC22: =IF(Inputs!B21>0,AA22/Inputs!B21,0) | AD22: =G22+T22 | AE22: =H22+W22 | AF22: =AD22+AE22 | AG22: =IF(M22>0,V22/M22,0) | AH22: =AH21+U22 | AI22: =IFERROR((1+IRR(VSTACK($AJ$8:INDEX($AJ:$AJ,ROW()-1),-U22+AA22)))^12-1,0) | AJ22: =-U22
A23: =A22+1 | B23: Month 16 | C23: =Z22 | D23: =AA22 | E23: =IF(A23<=12,0,INDEX($V$8:$V$127,A23-12)*Inputs!B13*MAX(0,Inputs!B10-12)/12) | F23: =IF(A23<=Inputs!B10,0,INDEX($T$8:$T$127,A23-Inputs!B10)) | G23: =AD22-F23 | H23: =AE22-IF(A23<=Inputs!B10,0,INDEX($W$8:$W$127,A23-Inputs!B10)) | I23: =H23*Inputs!B14/12 | J23: =C23+E23+F23-I23 | K23: =IF(Inputs!B19=1,MAX(0,Inputs!B5*1000000000-AH22),0) | L23: =MAX(0,J23+K23) | M23: =Inputs!B8*1000000 | N23: =Inputs!B9 | O23: =MAX(1,SQRT(L23/MAX(M23*MAX(N23,0.01)/(1+Inputs!B11),1))) | P23: =MIN(1,A23/12) | Q23: =IF(Inputs!B7=1,MAX(N23,L23*(1+Inputs!B11)/MAX(M23,1)),N23+(N23*O23-N23)*P23) | R23: =IF(Inputs!B7=1,L23*(1+Inputs!B11),M23*Q23) | S23: =R23/(1+Inputs!B11) | T23: =IF(Inputs!B7=1,L23,MIN(S23,L23)) | U23: =IF(Inputs!B19=1,MAX(0,T23-J23),0) | V23: =T23*(1+Inputs!B11) | W23: =V23-T23 | X23: =V23*Inputs!B13*MIN(12,Inputs!B10)/12 | Y23: =W23*Inputs!B14/12 | Z23: =J23+U23-T23+X23-Y23 | AA23: =D23+E23-I23+U23+X23-Y23 | AB23: =IF(U23>0,AB22*(1+Inputs!B15/12)+U23,AB22*(1+Inputs!B15/12)) | AC23: =IF(Inputs!B21>0,AA23/Inputs!B21,0) | AD23: =G23+T23 | AE23: =H23+W23 | AF23: =AD23+AE23 | AG23: =IF(M23>0,V23/M23,0) | AH23: =AH22+U23 | AI23: =IFERROR((1+IRR(VSTACK($AJ$8:INDEX($AJ:$AJ,ROW()-1),-U23+AA23)))^12-1,0) | AJ23: =-U23
A24: =A23+1 | B24: Month 17 | C24: =Z23 | D24: =AA23 | E24: =IF(A24<=12,0,INDEX($V$8:$V$127,A24-12)*Inputs!B13*MAX(0,Inputs!B10-12)/12) | F24: =IF(A24<=Inputs!B10,0,INDEX($T$8:$T$127,A24-Inputs!B10)) | G24: =AD23-F24 | H24: =AE23-IF(A24<=Inputs!B10,0,INDEX($W$8:$W$127,A24-Inputs!B10)) | I24: =H24*Inputs!B14/12 | J24: =C24+E24+F24-I24 | K24: =IF(Inputs!B19=1,MAX(0,Inputs!B5*1000000000-AH23),0) | L24: =MAX(0,J24+K24) | M24: =Inputs!B8*1000000 | N24: =Inputs!B9 | O24: =MAX(1,SQRT(L24/MAX(M24*MAX(N24,0.01)/(1+Inputs!B11),1))) | P24: =MIN(1,A24/12) | Q24: =IF(Inputs!B7=1,MAX(N24,L24*(1+Inputs!B11)/MAX(M24,1)),N24+(N24*O24-N24)*P24) | R24: =IF(Inputs!B7=1,L24*(1+Inputs!B11),M24*Q24) | S24: =R24/(1+Inputs!B11) | T24: =IF(Inputs!B7=1,L24,MIN(S24,L24)) | U24: =IF(Inputs!B19=1,MAX(0,T24-J24),0) | V24: =T24*(1+Inputs!B11) | W24: =V24-T24 | X24: =V24*Inputs!B13*MIN(12,Inputs!B10)/12 | Y24: =W24*Inputs!B14/12 | Z24: =J24+U24-T24+X24-Y24 | AA24: =D24+E24-I24+U24+X24-Y24 | AB24: =IF(U24>0,AB23*(1+Inputs!B15/12)+U24,AB23*(1+Inputs!B15/12)) | AC24: =IF(Inputs!B21>0,AA24/Inputs!B21,0) | AD24: =G24+T24 | AE24: =H24+W24 | AF24: =AD24+AE24 | AG24: =IF(M24>0,V24/M24,0) | AH24: =AH23+U24 | AI24: =IFERROR((1+IRR(VSTACK($AJ$8:INDEX($AJ:$AJ,ROW()-1),-U24+AA24)))^12-1,0) | AJ24: =-U24
A25: =A24+1 | B25: Month 18 | C25: =Z24 | D25: =AA24 | E25: =IF(A25<=12,0,INDEX($V$8:$V$127,A25-12)*Inputs!B13*MAX(0,Inputs!B10-12)/12) | F25: =IF(A25<=Inputs!B10,0,INDEX($T$8:$T$127,A25-Inputs!B10)) | G25: =AD24-F25 | H25: =AE24-IF(A25<=Inputs!B10,0,INDEX($W$8:$W$127,A25-Inputs!B10)) | I25: =H25*Inputs!B14/12 | J25: =C25+E25+F25-I25 | K25: =IF(Inputs!B19=1,MAX(0,Inputs!B5*1000000000-AH24),0) | L25: =MAX(0,J25+K25) | M25: =Inputs!B8*1000000 | N25: =Inputs!B9 | O25: =MAX(1,SQRT(L25/MAX(M25*MAX(N25,0.01)/(1+Inputs!B11),1))) | P25: =MIN(1,A25/12) | Q25: =IF(Inputs!B7=1,MAX(N25,L25*(1+Inputs!B11)/MAX(M25,1)),N25+(N25*O25-N25)*P25) | R25: =IF(Inputs!B7=1,L25*(1+Inputs!B11),M25*Q25) | S25: =R25/(1+Inputs!B11) | T25: =IF(Inputs!B7=1,L25,MIN(S25,L25)) | U25: =IF(Inputs!B19=1,MAX(0,T25-J25),0) | V25: =T25*(1+Inputs!B11) | W25: =V25-T25 | X25: =V25*Inputs!B13*MIN(12,Inputs!B10)/12 | Y25: =W25*Inputs!B14/12 | Z25: =J25+U25-T25+X25-Y25 | AA25: =D25+E25-I25+U25+X25-Y25 | AB25: =IF(U25>0,AB24*(1+Inputs!B15/12)+U25,AB24*(1+Inputs!B15/12)) | AC25: =IF(Inputs!B21>0,AA25/Inputs!B21,0) | AD25: =G25+T25 | AE25: =H25+W25 | AF25: =AD25+AE25 | AG25: =IF(M25>0,V25/M25,0) | AH25: =AH24+U25 | AI25: =IFERROR((1+IRR(VSTACK($AJ$8:INDEX($AJ:$AJ,ROW()-1),-U25+AA25)))^12-1,0) | AJ25: =-U25
A26: =A25+1 | B26: Month 19 | C26: =Z25 | D26: =AA25 | E26: =IF(A26<=12,0,INDEX($V$8:$V$127,A26-12)*Inputs!B13*MAX(0,Inputs!B10-12)/12) | F26: =IF(A26<=Inputs!B10,0,INDEX($T$8:$T$127,A26-Inputs!B10)) | G26: =AD25-F26 | H26: =AE25-IF(A26<=Inputs!B10,0,INDEX($W$8:$W$127,A26-Inputs!B10)) | I26: =H26*Inputs!B14/12 | J26: =C26+E26+F26-I26 | K26: =IF(Inputs!B19=1,MAX(0,Inputs!B5*1000000000-AH25),0) | L26: =MAX(0,J26+K26) | M26: =Inputs!B8*1000000 | N26: =Inputs!B9 | O26: =MAX(1,SQRT(L26/MAX(M26*MAX(N26,0.01)/(1+Inputs!B11),1))) | P26: =MIN(1,A26/12) | Q26: =IF(Inputs!B7=1,MAX(N26,L26*(1+Inputs!B11)/MAX(M26,1)),N26+(N26*O26-N26)*P26) | R26: =IF(Inputs!B7=1,L26*(1+Inputs!B11),M26*Q26) | S26: =R26/(1+Inputs!B11) | T26: =IF(Inputs!B7=1,L26,MIN(S26,L26)) | U26: =IF(Inputs!B19=1,MAX(0,T26-J26),0) | V26: =T26*(1+Inputs!B11) | W26: =V26-T26 | X26: =V26*Inputs!B13*MIN(12,Inputs!B10)/12 | Y26: =W26*Inputs!B14/12 | Z26: =J26+U26-T26+X26-Y26 | AA26: =D26+E26-I26+U26+X26-Y26 | AB26: =IF(U26>0,AB25*(1+Inputs!B15/12)+U26,AB25*(1+Inputs!B15/12)) | AC26: =IF(Inputs!B21>0,AA26/Inputs!B21,0) | AD26: =G26+T26 | AE26: =H26+W26 | AF26: =AD26+AE26 | AG26: =IF(M26>0,V26/M26,0) | AH26: =AH25+U26 | AI26: =IFERROR((1+IRR(VSTACK($AJ$8:INDEX($AJ:$AJ,ROW()-1),-U26+AA26)))^12-1,0) | AJ26: =-U26
A27: =A26+1 | B27: Month 20 | C27: =Z26 | D27: =AA26 | E27: =IF(A27<=12,0,INDEX($V$8:$V$127,A27-12)*Inputs!B13*MAX(0,Inputs!B10-12)/12) | F27: =IF(A27<=Inputs!B10,0,INDEX($T$8:$T$127,A27-Inputs!B10)) | G27: =AD26-F27 | H27: =AE26-IF(A27<=Inputs!B10,0,INDEX($W$8:$W$127,A27-Inputs!B10)) | I27: =H27*Inputs!B14/12 | J27: =C27+E27+F27-I27 | K27: =IF(Inputs!B19=1,MAX(0,Inputs!B5*1000000000-AH26),0) | L27: =MAX(0,J27+K27) | M27: =Inputs!B8*1000000 | N27: =Inputs!B9 | O27: =MAX(1,SQRT(L27/MAX(M27*MAX(N27,0.01)/(1+Inputs!B11),1))) | P27: =MIN(1,A27/12) | Q27: =IF(Inputs!B7=1,MAX(N27,L27*(1+Inputs!B11)/MAX(M27,1)),N27+(N27*O27-N27)*P27) | R27: =IF(Inputs!B7=1,L27*(1+Inputs!B11),M27*Q27) | S27: =R27/(1+Inputs!B11) | T27: =IF(Inputs!B7=1,L27,MIN(S27,L27)) | U27: =IF(Inputs!B19=1,MAX(0,T27-J27),0) | V27: =T27*(1+Inputs!B11) | W27: =V27-T27 | X27: =V27*Inputs!B13*MIN(12,Inputs!B10)/12 | Y27: =W27*Inputs!B14/12 | Z27: =J27+U27-T27+X27-Y27 | AA27: =D27+E27-I27+U27+X27-Y27 | AB27: =IF(U27>0,AB26*(1+Inputs!B15/12)+U27,AB26*(1+Inputs!B15/12)) | AC27: =IF(Inputs!B21>0,AA27/Inputs!B21,0) | AD27: =G27+T27 | AE27: =H27+W27 | AF27: =AD27+AE27 | AG27: =IF(M27>0,V27/M27,0) | AH27: =AH26+U27 | AI27: =IFERROR((1+IRR(VSTACK($AJ$8:INDEX($AJ:$AJ,ROW()-1),-U27+AA27)))^12-1,0) | AJ27: =-U27
A28: =A27+1 | B28: Month 21 | C28: =Z27 | D28: =AA27 | E28: =IF(A28<=12,0,INDEX($V$8:$V$127,A28-12)*Inputs!B13*MAX(0,Inputs!B10-12)/12) | F28: =IF(A28<=Inputs!B10,0,INDEX($T$8:$T$127,A28-Inputs!B10)) | G28: =AD27-F28 | H28: =AE27-IF(A28<=Inputs!B10,0,INDEX($W$8:$W$127,A28-Inputs!B10)) | I28: =H28*Inputs!B14/12 | J28: =C28+E28+F28-I28 | K28: =IF(Inputs!B19=1,MAX(0,Inputs!B5*1000000000-AH27),0) | L28: =MAX(0,J28+K28) | M28: =Inputs!B8*1000000 | N28: =Inputs!B9 | O28: =MAX(1,SQRT(L28/MAX(M28*MAX(N28,0.01)/(1+Inputs!B11),1))) | P28: =MIN(1,A28/12) | Q28: =IF(Inputs!B7=1,MAX(N28,L28*(1+Inputs!B11)/MAX(M28,1)),N28+(N28*O28-N28)*P28) | R28: =IF(Inputs!B7=1,L28*(1+Inputs!B11),M28*Q28) | S28: =R28/(1+Inputs!B11) | T28: =IF(Inputs!B7=1,L28,MIN(S28,L28)) | U28: =IF(Inputs!B19=1,MAX(0,T28-J28),0) | V28: =T28*(1+Inputs!B11) | W28: =V28-T28 | X28: =V28*Inputs!B13*MIN(12,Inputs!B10)/12 | Y28: =W28*Inputs!B14/12 | Z28: =J28+U28-T28+X28-Y28 | AA28: =D28+E28-I28+U28+X28-Y28 | AB28: =IF(U28>0,AB27*(1+Inputs!B15/12)+U28,AB27*(1+Inputs!B15/12)) | AC28: =IF(Inputs!B21>0,AA28/Inputs!B21,0) | AD28: =G28+T28 | AE28: =H28+W28 | AF28: =AD28+AE28 | AG28: =IF(M28>0,V28/M28,0) | AH28: =AH27+U28 | AI28: =IFERROR((1+IRR(VSTACK($AJ$8:INDEX($AJ:$AJ,ROW()-1),-U28+AA28)))^12-1,0) | AJ28: =-U28
A29: =A28+1 | B29: Month 22 | C29: =Z28 | D29: =AA28 | E29: =IF(A29<=12,0,INDEX($V$8:$V$127,A29-12)*Inputs!B13*MAX(0,Inputs!B10-12)/12) | F29: =IF(A29<=Inputs!B10,0,INDEX($T$8:$T$127,A29-Inputs!B10)) | G29: =AD28-F29 | H29: =AE28-IF(A29<=Inputs!B10,0,INDEX($W$8:$W$127,A29-Inputs!B10)) | I29: =H29*Inputs!B14/12 | J29: =C29+E29+F29-I29 | K29: =IF(Inputs!B19=1,MAX(0,Inputs!B5*1000000000-AH28),0) | L29: =MAX(0,J29+K29) | M29: =Inputs!B8*1000000 | N29: =Inputs!B9 | O29: =MAX(1,SQRT(L29/MAX(M29*MAX(N29,0.01)/(1+Inputs!B11),1))) | P29: =MIN(1,A29/12) | Q29: =IF(Inputs!B7=1,MAX(N29,L29*(1+Inputs!B11)/MAX(M29,1)),N29+(N29*O29-N29)*P29) | R29: =IF(Inputs!B7=1,L29*(1+Inputs!B11),M29*Q29) | S29: =R29/(1+Inputs!B11) | T29: =IF(Inputs!B7=1,L29,MIN(S29,L29)) | U29: =IF(Inputs!B19=1,MAX(0,T29-J29),0) | V29: =T29*(1+Inputs!B11) | W29: =V29-T29 | X29: =V29*Inputs!B13*MIN(12,Inputs!B10)/12 | Y29: =W29*Inputs!B14/12 | Z29: =J29+U29-T29+X29-Y29 | AA29: =D29+E29-I29+U29+X29-Y29 | AB29: =IF(U29>0,AB28*(1+Inputs!B15/12)+U29,AB28*(1+Inputs!B15/12)) | AC29: =IF(Inputs!B21>0,AA29/Inputs!B21,0) | AD29: =G29+T29 | AE29: =H29+W29 | AF29: =AD29+AE29 | AG29: =IF(M29>0,V29/M29,0) | AH29: =AH28+U29 | AI29: =IFERROR((1+IRR(VSTACK($AJ$8:INDEX($AJ:$AJ,ROW()-1),-U29+AA29)))^12-1,0) | AJ29: =-U29
A30: =A29+1 | B30: Month 23 | C30: =Z29 | D30: =AA29 | E30: =IF(A30<=12,0,INDEX($V$8:$V$127,A30-12)*Inputs!B13*MAX(0,Inputs!B10-12)/12) | F30: =IF(A30<=Inputs!B10,0,INDEX($T$8:$T$127,A30-Inputs!B10)) | G30: =AD29-F30 | H30: =AE29-IF(A30<=Inputs!B10,0,INDEX($W$8:$W$127,A30-Inputs!B10)) | I30: =H30*Inputs!B14/12 | J30: =C30+E30+F30-I30 | K30: =IF(Inputs!B19=1,MAX(0,Inputs!B5*1000000000-AH29),0) | L30: =MAX(0,J30+K30) | M30: =Inputs!B8*1000000 | N30: =Inputs!B9 | O30: =MAX(1,SQRT(L30/MAX(M30*MAX(N30,0.01)/(1+Inputs!B11),1))) | P30: =MIN(1,A30/12) | Q30: =IF(Inputs!B7=1,MAX(N30,L30*(1+Inputs!B11)/MAX(M30,1)),N30+(N30*O30-N30)*P30) | R30: =IF(Inputs!B7=1,L30*(1+Inputs!B11),M30*Q30) | S30: =R30/(1+Inputs!B11) | T30: =IF(Inputs!B7=1,L30,MIN(S30,L30)) | U30: =IF(Inputs!B19=1,MAX(0,T30-J30),0) | V30: =T30*(1+Inputs!B11) | W30: =V30-T30 | X30: =V30*Inputs!B13*MIN(12,Inputs!B10)/12 | Y30: =W30*Inputs!B14/12 | Z30: =J30+U30-T30+X30-Y30 | AA30: =D30+E30-I30+U30+X30-Y30 | AB30: =IF(U30>0,AB29*(1+Inputs!B15/12)+U30,AB29*(1+Inputs!B15/12)) | AC30: =IF(Inputs!B21>0,AA30/Inputs!B21,0) | AD30: =G30+T30 | AE30: =H30+W30 | AF30: =AD30+AE30 | AG30: =IF(M30>0,V30/M30,0) | AH30: =AH29+U30 | AI30: =IFERROR((1+IRR(VSTACK($AJ$8:INDEX($AJ:$AJ,ROW()-1),-U30+AA30)))^12-1,0) | AJ30: =-U30
A31: =A30+1 | B31: Month 24 | C31: =Z30 | D31: =AA30 | E31: =IF(A31<=12,0,INDEX($V$8:$V$127,A31-12)*Inputs!B13*MAX(0,Inputs!B10-12)/12) | F31: =IF(A31<=Inputs!B10,0,INDEX($T$8:$T$127,A31-Inputs!B10)) | G31: =AD30-F31 | H31: =AE30-IF(A31<=Inputs!B10,0,INDEX($W$8:$W$127,A31-Inputs!B10)) | I31: =H31*Inputs!B14/12 | J31: =C31+E31+F31-I31 | K31: =IF(Inputs!B19=1,MAX(0,Inputs!B5*1000000000-AH30),0) | L31: =MAX(0,J31+K31) | M31: =Inputs!B8*1000000 | N31: =Inputs!B9 | O31: =MAX(1,SQRT(L31/MAX(M31*MAX(N31,0.01)/(1+Inputs!B11),1))) | P31: =MIN(1,A31/12) | Q31: =IF(Inputs!B7=1,MAX(N31,L31*(1+Inputs!B11)/MAX(M31,1)),N31+(N31*O31-N31)*P31) | R31: =IF(Inputs!B7=1,L31*(1+Inputs!B11),M31*Q31) | S31: =R31/(1+Inputs!B11) | T31: =IF(Inputs!B7=1,L31,MIN(S31,L31)) | U31: =IF(Inputs!B19=1,MAX(0,T31-J31),0) | V31: =T31*(1+Inputs!B11) | W31: =V31-T31 | X31: =V31*Inputs!B13*MIN(12,Inputs!B10)/12 | Y31: =W31*Inputs!B14/12 | Z31: =J31+U31-T31+X31-Y31 | AA31: =D31+E31-I31+U31+X31-Y31 | AB31: =IF(U31>0,AB30*(1+Inputs!B15/12)+U31,AB30*(1+Inputs!B15/12)) | AC31: =IF(Inputs!B21>0,AA31/Inputs!B21,0) | AD31: =G31+T31 | AE31: =H31+W31 | AF31: =AD31+AE31 | AG31: =IF(M31>0,V31/M31,0) | AH31: =AH30+U31 | AI31: =IFERROR((1+IRR(VSTACK($AJ$8:INDEX($AJ:$AJ,ROW()-1),-U31+AA31)))^12-1,0) | AJ31: =-U31
A32: =A31+1 | B32: Month 25 | C32: =Z31 | D32: =AA31 | E32: =IF(A32<=12,0,INDEX($V$8:$V$127,A32-12)*Inputs!B13*MAX(0,Inputs!B10-12)/12) | F32: =IF(A32<=Inputs!B10,0,INDEX($T$8:$T$127,A32-Inputs!B10)) | G32: =AD31-F32 | H32: =AE31-IF(A32<=Inputs!B10,0,INDEX($W$8:$W$127,A32-Inputs!B10)) | I32: =H32*Inputs!B14/12 | J32: =C32+E32+F32-I32 | K32: =IF(Inputs!B19=1,MAX(0,Inputs!B5*1000000000-AH31),0) | L32: =MAX(0,J32+K32) | M32: =Inputs!B8*1000000 | N32: =Inputs!B9 | O32: =MAX(1,SQRT(L32/MAX(M32*MAX(N32,0.01)/(1+Inputs!B11),1))) | P32: =MIN(1,A32/12) | Q32: =IF(Inputs!B7=1,MAX(N32,L32*(1+Inputs!B11)/MAX(M32,1)),N32+(N32*O32-N32)*P32) | R32: =IF(Inputs!B7=1,L32*(1+Inputs!B11),M32*Q32) | S32: =R32/(1+Inputs!B11) | T32: =IF(Inputs!B7=1,L32,MIN(S32,L32)) | U32: =IF(Inputs!B19=1,MAX(0,T32-J32),0) | V32: =T32*(1+Inputs!B11) | W32: =V32-T32 | X32: =V32*Inputs!B13*MIN(12,Inputs!B10)/12 | Y32: =W32*Inputs!B14/12 | Z32: =J32+U32-T32+X32-Y32 | AA32: =D32+E32-I32+U32+X32-Y32 | AB32: =IF(U32>0,AB31*(1+Inputs!B15/12)+U32,AB31*(1+Inputs!B15/12)) | AC32: =IF(Inputs!B21>0,AA32/Inputs!B21,0) | AD32: =G32+T32 | AE32: =H32+W32 | AF32: =AD32+AE32 | AG32: =IF(M32>0,V32/M32,0) | AH32: =AH31+U32 | AI32: =IFERROR((1+IRR(VSTACK($AJ$8:INDEX($AJ:$AJ,ROW()-1),-U32+AA32)))^12-1,0) | AJ32: =-U32
A33: =A32+1 | B33: Month 26 | C33: =Z32 | D33: =AA32 | E33: =IF(A33<=12,0,INDEX($V$8:$V$127,A33-12)*Inputs!B13*MAX(0,Inputs!B10-12)/12) | F33: =IF(A33<=Inputs!B10,0,INDEX($T$8:$T$127,A33-Inputs!B10)) | G33: =AD32-F33 | H33: =AE32-IF(A33<=Inputs!B10,0,INDEX($W$8:$W$127,A33-Inputs!B10)) | I33: =H33*Inputs!B14/12 | J33: =C33+E33+F33-I33 | K33: =IF(Inputs!B19=1,MAX(0,Inputs!B5*1000000000-AH32),0) | L33: =MAX(0,J33+K33) | M33: =Inputs!B8*1000000 | N33: =Inputs!B9 | O33: =MAX(1,SQRT(L33/MAX(M33*MAX(N33,0.01)/(1+Inputs!B11),1))) | P33: =MIN(1,A33/12) | Q33: =IF(Inputs!B7=1,MAX(N33,L33*(1+Inputs!B11)/MAX(M33,1)),N33+(N33*O33-N33)*P33) | R33: =IF(Inputs!B7=1,L33*(1+Inputs!B11),M33*Q33) | S33: =R33/(1+Inputs!B11) | T33: =IF(Inputs!B7=1,L33,MIN(S33,L33)) | U33: =IF(Inputs!B19=1,MAX(0,T33-J33),0) | V33: =T33*(1+Inputs!B11) | W33: =V33-T33 | X33: =V33*Inputs!B13*MIN(12,Inputs!B10)/12 | Y33: =W33*Inputs!B14/12 | Z33: =J33+U33-T33+X33-Y33 | AA33: =D33+E33-I33+U33+X33-Y33 | AB33: =IF(U33>0,AB32*(1+Inputs!B15/12)+U33,AB32*(1+Inputs!B15/12)) | AC33: =IF(Inputs!B21>0,AA33/Inputs!B21,0) | AD33: =G33+T33 | AE33: =H33+W33 | AF33: =AD33+AE33 | AG33: =IF(M33>0,V33/M33,0) | AH33: =AH32+U33 | AI33: =IFERROR((1+IRR(VSTACK($AJ$8:INDEX($AJ:$AJ,ROW()-1),-U33+AA33)))^12-1,0) | AJ33: =-U33
A34: =A33+1 | B34: Month 27 | C34: =Z33 | D34: =AA33 | E34: =IF(A34<=12,0,INDEX($V$8:$V$127,A34-12)*Inputs!B13*MAX(0,Inputs!B10-12)/12) | F34: =IF(A34<=Inputs!B10,0,INDEX($T$8:$T$127,A34-Inputs!B10)) | G34: =AD33-F34 | H34: =AE33-IF(A34<=Inputs!B10,0,INDEX($W$8:$W$127,A34-Inputs!B10)) | I34: =H34*Inputs!B14/12 | J34: =C34+E34+F34-I34 | K34: =IF(Inputs!B19=1,MAX(0,Inputs!B5*1000000000-AH33),0) | L34: =MAX(0,J34+K34) | M34: =Inputs!B8*1000000 | N34: =Inputs!B9 | O34: =MAX(1,SQRT(L34/MAX(M34*MAX(N34,0.01)/(1+Inputs!B11),1))) | P34: =MIN(1,A34/12) | Q34: =IF(Inputs!B7=1,MAX(N34,L34*(1+Inputs!B11)/MAX(M34,1)),N34+(N34*O34-N34)*P34) | R34: =IF(Inputs!B7=1,L34*(1+Inputs!B11),M34*Q34) | S34: =R34/(1+Inputs!B11) | T34: =IF(Inputs!B7=1,L34,MIN(S34,L34)) | U34: =IF(Inputs!B19=1,MAX(0,T34-J34),0) | V34: =T34*(1+Inputs!B11) | W34: =V34-T34 | X34: =V34*Inputs!B13*MIN(12,Inputs!B10)/12 | Y34: =W34*Inputs!B14/12 | Z34: =J34+U34-T34+X34-Y34 | AA34: =D34+E34-I34+U34+X34-Y34 | AB34: =IF(U34>0,AB33*(1+Inputs!B15/12)+U34,AB33*(1+Inputs!B15/12)) | AC34: =IF(Inputs!B21>0,AA34/Inputs!B21,0) | AD34: =G34+T34 | AE34: =H34+W34 | AF34: =AD34+AE34 | AG34: =IF(M34>0,V34/M34,0) | AH34: =AH33+U34 | AI34: =IFERROR((1+IRR(VSTACK($AJ$8:INDEX($AJ:$AJ,ROW()-1),-U34+AA34)))^12-1,0) | AJ34: =-U34
A35: =A34+1 | B35: Month 28 | C35: =Z34 | D35: =AA34 | E35: =IF(A35<=12,0,INDEX($V$8:$V$127,A35-12)*Inputs!B13*MAX(0,Inputs!B10-12)/12) | F35: =IF(A35<=Inputs!B10,0,INDEX($T$8:$T$127,A35-Inputs!B10)) | G35: =AD34-F35 | H35: =AE34-IF(A35<=Inputs!B10,0,INDEX($W$8:$W$127,A35-Inputs!B10)) | I35: =H35*Inputs!B14/12 | J35: =C35+E35+F35-I35 | K35: =IF(Inputs!B19=1,MAX(0,Inputs!B5*1000000000-AH34),0) | L35: =MAX(0,J35+K35) | M35: =Inputs!B8*1000000 | N35: =Inputs!B9 | O35: =MAX(1,SQRT(L35/MAX(M35*MAX(N35,0.01)/(1+Inputs!B11),1))) | P35: =MIN(1,A35/12) | Q35: =IF(Inputs!B7=1,MAX(N35,L35*(1+Inputs!B11)/MAX(M35,1)),N35+(N35*O35-N35)*P35) | R35: =IF(Inputs!B7=1,L35*(1+Inputs!B11),M35*Q35) | S35: =R35/(1+Inputs!B11) | T35: =IF(Inputs!B7=1,L35,MIN(S35,L35)) | U35: =IF(Inputs!B19=1,MAX(0,T35-J35),0) | V35: =T35*(1+Inputs!B11) | W35: =V35-T35 | X35: =V35*Inputs!B13*MIN(12,Inputs!B10)/12 | Y35: =W35*Inputs!B14/12 | Z35: =J35+U35-T35+X35-Y35 | AA35: =D35+E35-I35+U35+X35-Y35 | AB35: =IF(U35>0,AB34*(1+Inputs!B15/12)+U35,AB34*(1+Inputs!B15/12)) | AC35: =IF(Inputs!B21>0,AA35/Inputs!B21,0) | AD35: =G35+T35 | AE35: =H35+W35 | AF35: =AD35+AE35 | AG35: =IF(M35>0,V35/M35,0) | AH35: =AH34+U35 | AI35: =IFERROR((1+IRR(VSTACK($AJ$8:INDEX($AJ:$AJ,ROW()-1),-U35+AA35)))^12-1,0) | AJ35: =-U35
A36: =A35+1 | B36: Month 29 | C36: =Z35 | D36: =AA35 | E36: =IF(A36<=12,0,INDEX($V$8:$V$127,A36-12)*Inputs!B13*MAX(0,Inputs!B10-12)/12) | F36: =IF(A36<=Inputs!B10,0,INDEX($T$8:$T$127,A36-Inputs!B10)) | G36: =AD35-F36 | H36: =AE35-IF(A36<=Inputs!B10,0,INDEX($W$8:$W$127,A36-Inputs!B10)) | I36: =H36*Inputs!B14/12 | J36: =C36+E36+F36-I36 | K36: =IF(Inputs!B19=1,MAX(0,Inputs!B5*1000000000-AH35),0) | L36: =MAX(0,J36+K36) | M36: =Inputs!B8*1000000 | N36: =Inputs!B9 | O36: =MAX(1,SQRT(L36/MAX(M36*MAX(N36,0.01)/(1+Inputs!B11),1))) | P36: =MIN(1,A36/12) | Q36: =IF(Inputs!B7=1,MAX(N36,L36*(1+Inputs!B11)/MAX(M36,1)),N36+(N36*O36-N36)*P36) | R36: =IF(Inputs!B7=1,L36*(1+Inputs!B11),M36*Q36) | S36: =R36/(1+Inputs!B11) | T36: =IF(Inputs!B7=1,L36,MIN(S36,L36)) | U36: =IF(Inputs!B19=1,MAX(0,T36-J36),0) | V36: =T36*(1+Inputs!B11) | W36: =V36-T36 | X36: =V36*Inputs!B13*MIN(12,Inputs!B10)/12 | Y36: =W36*Inputs!B14/12 | Z36: =J36+U36-T36+X36-Y36 | AA36: =D36+E36-I36+U36+X36-Y36 | AB36: =IF(U36>0,AB35*(1+Inputs!B15/12)+U36,AB35*(1+Inputs!B15/12)) | AC36: =IF(Inputs!B21>0,AA36/Inputs!B21,0) | AD36: =G36+T36 | AE36: =H36+W36 | AF36: =AD36+AE36 | AG36: =IF(M36>0,V36/M36,0) | AH36: =AH35+U36 | AI36: =IFERROR((1+IRR(VSTACK($AJ$8:INDEX($AJ:$AJ,ROW()-1),-U36+AA36)))^12-1,0) | AJ36: =-U36
A37: =A36+1 | B37: Month 30 | C37: =Z36 | D37: =AA36 | E37: =IF(A37<=12,0,INDEX($V$8:$V$127,A37-12)*Inputs!B13*MAX(0,Inputs!B10-12)/12) | F37: =IF(A37<=Inputs!B10,0,INDEX($T$8:$T$127,A37-Inputs!B10)) | G37: =AD36-F37 | H37: =AE36-IF(A37<=Inputs!B10,0,INDEX($W$8:$W$127,A37-Inputs!B10)) | I37: =H37*Inputs!B14/12 | J37: =C37+E37+F37-I37 | K37: =IF(Inputs!B19=1,MAX(0,Inputs!B5*1000000000-AH36),0) | L37: =MAX(0,J37+K37) | M37: =Inputs!B8*1000000 | N37: =Inputs!B9 | O37: =MAX(1,SQRT(L37/MAX(M37*MAX(N37,0.01)/(1+Inputs!B11),1))) | P37: =MIN(1,A37/12) | Q37: =IF(Inputs!B7=1,MAX(N37,L37*(1+Inputs!B11)/MAX(M37,1)),N37+(N37*O37-N37)*P37) | R37: =IF(Inputs!B7=1,L37*(1+Inputs!B11),M37*Q37) | S37: =R37/(1+Inputs!B11) | T37: =IF(Inputs!B7=1,L37,MIN(S37,L37)) | U37: =IF(Inputs!B19=1,MAX(0,T37-J37),0) | V37: =T37*(1+Inputs!B11) | W37: =V37-T37 | X37: =V37*Inputs!B13*MIN(12,Inputs!B10)/12 | Y37: =W37*Inputs!B14/12 | Z37: =J37+U37-T37+X37-Y37 | AA37: =D37+E37-I37+U37+X37-Y37 | AB37: =IF(U37>0,AB36*(1+Inputs!B15/12)+U37,AB36*(1+Inputs!B15/12)) | AC37: =IF(Inputs!B21>0,AA37/Inputs!B21,0) | AD37: =G37+T37 | AE37: =H37+W37 | AF37: =AD37+AE37 | AG37: =IF(M37>0,V37/M37,0) | AH37: =AH36+U37 | AI37: =IFERROR((1+IRR(VSTACK($AJ$8:INDEX($AJ:$AJ,ROW()-1),-U37+AA37)))^12-1,0) | AJ37: =-U37
A38: =A37+1 | B38: Month 31 | C38: =Z37 | D38: =AA37 | E38: =IF(A38<=12,0,INDEX($V$8:$V$127,A38-12)*Inputs!B13*MAX(0,Inputs!B10-12)/12) | F38: =IF(A38<=Inputs!B10,0,INDEX($T$8:$T$127,A38-Inputs!B10)) | G38: =AD37-F38 | H38: =AE37-IF(A38<=Inputs!B10,0,INDEX($W$8:$W$127,A38-Inputs!B10)) | I38: =H38*Inputs!B14/12 | J38: =C38+E38+F38-I38 | K38: =IF(Inputs!B19=1,MAX(0,Inputs!B5*1000000000-AH37),0) | L38: =MAX(0,J38+K38) | M38: =Inputs!B8*1000000 | N38: =Inputs!B9 | O38: =MAX(1,SQRT(L38/MAX(M38*MAX(N38,0.01)/(1+Inputs!B11),1))) | P38: =MIN(1,A38/12) | Q38: =IF(Inputs!B7=1,MAX(N38,L38*(1+Inputs!B11)/MAX(M38,1)),N38+(N38*O38-N38)*P38) | R38: =IF(Inputs!B7=1,L38*(1+Inputs!B11),M38*Q38) | S38: =R38/(1+Inputs!B11) | T38: =IF(Inputs!B7=1,L38,MIN(S38,L38)) | U38: =IF(Inputs!B19=1,MAX(0,T38-J38),0) | V38: =T38*(1+Inputs!B11) | W38: =V38-T38 | X38: =V38*Inputs!B13*MIN(12,Inputs!B10)/12 | Y38: =W38*Inputs!B14/12 | Z38: =J38+U38-T38+X38-Y38 | AA38: =D38+E38-I38+U38+X38-Y38 | AB38: =IF(U38>0,AB37*(1+Inputs!B15/12)+U38,AB37*(1+Inputs!B15/12)) | AC38: =IF(Inputs!B21>0,AA38/Inputs!B21,0) | AD38: =G38+T38 | AE38: =H38+W38 | AF38: =AD38+AE38 | AG38: =IF(M38>0,V38/M38,0) | AH38: =AH37+U38 | AI38: =IFERROR((1+IRR(VSTACK($AJ$8:INDEX($AJ:$AJ,ROW()-1),-U38+AA38)))^12-1,0) | AJ38: =-U38
A39: =A38+1 | B39: Month 32 | C39: =Z38 | D39: =AA38 | E39: =IF(A39<=12,0,INDEX($V$8:$V$127,A39-12)*Inputs!B13*MAX(0,Inputs!B10-12)/12) | F39: =IF(A39<=Inputs!B10,0,INDEX($T$8:$T$127,A39-Inputs!B10)) | G39: =AD38-F39 | H39: =AE38-IF(A39<=Inputs!B10,0,INDEX($W$8:$W$127,A39-Inputs!B10)) | I39: =H39*Inputs!B14/12 | J39: =C39+E39+F39-I39 | K39: =IF(Inputs!B19=1,MAX(0,Inputs!B5*1000000000-AH38),0) | L39: =MAX(0,J39+K39) | M39: =Inputs!B8*1000000 | N39: =Inputs!B9 | O39: =MAX(1,SQRT(L39/MAX(M39*MAX(N39,0.01)/(1+Inputs!B11),1))) | P39: =MIN(1,A39/12) | Q39: =IF(Inputs!B7=1,MAX(N39,L39*(1+Inputs!B11)/MAX(M39,1)),N39+(N39*O39-N39)*P39) | R39: =IF(Inputs!B7=1,L39*(1+Inputs!B11),M39*Q39) | S39: =R39/(1+Inputs!B11) | T39: =IF(Inputs!B7=1,L39,MIN(S39,L39)) | U39: =IF(Inputs!B19=1,MAX(0,T39-J39),0) | V39: =T39*(1+Inputs!B11) | W39: =V39-T39 | X39: =V39*Inputs!B13*MIN(12,Inputs!B10)/12 | Y39: =W39*Inputs!B14/12 | Z39: =J39+U39-T39+X39-Y39 | AA39: =D39+E39-I39+U39+X39-Y39 | AB39: =IF(U39>0,AB38*(1+Inputs!B15/12)+U39,AB38*(1+Inputs!B15/12)) | AC39: =IF(Inputs!B21>0,AA39/Inputs!B21,0) | AD39: =G39+T39 | AE39: =H39+W39 | AF39: =AD39+AE39 | AG39: =IF(M39>0,V39/M39,0) | AH39: =AH38+U39 | AI39: =IFERROR((1+IRR(VSTACK($AJ$8:INDEX($AJ:$AJ,ROW()-1),-U39+AA39)))^12-1,0) | AJ39: =-U39
A40: =A39+1 | B40: Month 33 | C40: =Z39 | D40: =AA39 | E40: =IF(A40<=12,0,INDEX($V$8:$V$127,A40-12)*Inputs!B13*MAX(0,Inputs!B10-12)/12) | F40: =IF(A40<=Inputs!B10,0,INDEX($T$8:$T$127,A40-Inputs!B10)) | G40: =AD39-F40 | H40: =AE39-IF(A40<=Inputs!B10,0,INDEX($W$8:$W$127,A40-Inputs!B10)) | I40: =H40*Inputs!B14/12 | J40: =C40+E40+F40-I40 | K40: =IF(Inputs!B19=1,MAX(0,Inputs!B5*1000000000-AH39),0) | L40: =MAX(0,J40+K40) | M40: =Inputs!B8*1000000 | N40: =Inputs!B9 | O40: =MAX(1,SQRT(L40/MAX(M40*MAX(N40,0.01)/(1+Inputs!B11),1))) | P40: =MIN(1,A40/12) | Q40: =IF(Inputs!B7=1,MAX(N40,L40*(1+Inputs!B11)/MAX(M40,1)),N40+(N40*O40-N40)*P40) | R40: =IF(Inputs!B7=1,L40*(1+Inputs!B11),M40*Q40) | S40: =R40/(1+Inputs!B11) | T40: =IF(Inputs!B7=1,L40,MIN(S40,L40)) | U40: =IF(Inputs!B19=1,MAX(0,T40-J40),0) | V40: =T40*(1+Inputs!B11) | W40: =V40-T40 | X40: =V40*Inputs!B13*MIN(12,Inputs!B10)/12 | Y40: =W40*Inputs!B14/12 | Z40: =J40+U40-T40+X40-Y40 | AA40: =D40+E40-I40+U40+X40-Y40 | AB40: =IF(U40>0,AB39*(1+Inputs!B15/12)+U40,AB39*(1+Inputs!B15/12)) | AC40: =IF(Inputs!B21>0,AA40/Inputs!B21,0) | AD40: =G40+T40 | AE40: =H40+W40 | AF40: =AD40+AE40 | AG40: =IF(M40>0,V40/M40,0) | AH40: =AH39+U40 | AI40: =IFERROR((1+IRR(VSTACK($AJ$8:INDEX($AJ:$AJ,ROW()-1),-U40+AA40)))^12-1,0) | AJ40: =-U40
A41: =A40+1 | B41: Month 34 | C41: =Z40 | D41: =AA40 | E41: =IF(A41<=12,0,INDEX($V$8:$V$127,A41-12)*Inputs!B13*MAX(0,Inputs!B10-12)/12) | F41: =IF(A41<=Inputs!B10,0,INDEX($T$8:$T$127,A41-Inputs!B10)) | G41: =AD40-F41 | H41: =AE40-IF(A41<=Inputs!B10,0,INDEX($W$8:$W$127,A41-Inputs!B10)) | I41: =H41*Inputs!B14/12 | J41: =C41+E41+F41-I41 | K41: =IF(Inputs!B19=1,MAX(0,Inputs!B5*1000000000-AH40),0) | L41: =MAX(0,J41+K41) | M41: =Inputs!B8*1000000 | N41: =Inputs!B9 | O41: =MAX(1,SQRT(L41/MAX(M41*MAX(N41,0.01)/(1+Inputs!B11),1))) | P41: =MIN(1,A41/12) | Q41: =IF(Inputs!B7=1,MAX(N41,L41*(1+Inputs!B11)/MAX(M41,1)),N41+(N41*O41-N41)*P41) | R41: =IF(Inputs!B7=1,L41*(1+Inputs!B11),M41*Q41) | S41: =R41/(1+Inputs!B11) | T41: =IF(Inputs!B7=1,L41,MIN(S41,L41)) | U41: =IF(Inputs!B19=1,MAX(0,T41-J41),0) | V41: =T41*(1+Inputs!B11) | W41: =V41-T41 | X41: =V41*Inputs!B13*MIN(12,Inputs!B10)/12 | Y41: =W41*Inputs!B14/12 | Z41: =J41+U41-T41+X41-Y41 | AA41: =D41+E41-I41+U41+X41-Y41 | AB41: =IF(U41>0,AB40*(1+Inputs!B15/12)+U41,AB40*(1+Inputs!B15/12)) | AC41: =IF(Inputs!B21>0,AA41/Inputs!B21,0) | AD41: =G41+T41 | AE41: =H41+W41 | AF41: =AD41+AE41 | AG41: =IF(M41>0,V41/M41,0) | AH41: =AH40+U41 | AI41: =IFERROR((1+IRR(VSTACK($AJ$8:INDEX($AJ:$AJ,ROW()-1),-U41+AA41)))^12-1,0) | AJ41: =-U41
A42: =A41+1 | B42: Month 35 | C42: =Z41 | D42: =AA41 | E42: =IF(A42<=12,0,INDEX($V$8:$V$127,A42-12)*Inputs!B13*MAX(0,Inputs!B10-12)/12) | F42: =IF(A42<=Inputs!B10,0,INDEX($T$8:$T$127,A42-Inputs!B10)) | G42: =AD41-F42 | H42: =AE41-IF(A42<=Inputs!B10,0,INDEX($W$8:$W$127,A42-Inputs!B10)) | I42: =H42*Inputs!B14/12 | J42: =C42+E42+F42-I42 | K42: =IF(Inputs!B19=1,MAX(0,Inputs!B5*1000000000-AH41),0) | L42: =MAX(0,J42+K42) | M42: =Inputs!B8*1000000 | N42: =Inputs!B9 | O42: =MAX(1,SQRT(L42/MAX(M42*MAX(N42,0.01)/(1+Inputs!B11),1))) | P42: =MIN(1,A42/12) | Q42: =IF(Inputs!B7=1,MAX(N42,L42*(1+Inputs!B11)/MAX(M42,1)),N42+(N42*O42-N42)*P42) | R42: =IF(Inputs!B7=1,L42*(1+Inputs!B11),M42*Q42) | S42: =R42/(1+Inputs!B11) | T42: =IF(Inputs!B7=1,L42,MIN(S42,L42)) | U42: =IF(Inputs!B19=1,MAX(0,T42-J42),0) | V42: =T42*(1+Inputs!B11) | W42: =V42-T42 | X42: =V42*Inputs!B13*MIN(12,Inputs!B10)/12 | Y42: =W42*Inputs!B14/12 | Z42: =J42+U42-T42+X42-Y42 | AA42: =D42+E42-I42+U42+X42-Y42 | AB42: =IF(U42>0,AB41*(1+Inputs!B15/12)+U42,AB41*(1+Inputs!B15/12)) | AC42: =IF(Inputs!B21>0,AA42/Inputs!B21,0) | AD42: =G42+T42 | AE42: =H42+W42 | AF42: =AD42+AE42 | AG42: =IF(M42>0,V42/M42,0) | AH42: =AH41+U42 | AI42: =IFERROR((1+IRR(VSTACK($AJ$8:INDEX($AJ:$AJ,ROW()-1),-U42+AA42)))^12-1,0) | AJ42: =-U42
A43: =A42+1 | B43: Month 36 | C43: =Z42 | D43: =AA42 | E43: =IF(A43<=12,0,INDEX($V$8:$V$127,A43-12)*Inputs!B13*MAX(0,Inputs!B10-12)/12) | F43: =IF(A43<=Inputs!B10,0,INDEX($T$8:$T$127,A43-Inputs!B10)) | G43: =AD42-F43 | H43: =AE42-IF(A43<=Inputs!B10,0,INDEX($W$8:$W$127,A43-Inputs!B10)) | I43: =H43*Inputs!B14/12 | J43: =C43+E43+F43-I43 | K43: =IF(Inputs!B19=1,MAX(0,Inputs!B5*1000000000-AH42),0) | L43: =MAX(0,J43+K43) | M43: =Inputs!B8*1000000 | N43: =Inputs!B9 | O43: =MAX(1,SQRT(L43/MAX(M43*MAX(N43,0.01)/(1+Inputs!B11),1))) | P43: =MIN(1,A43/12) | Q43: =IF(Inputs!B7=1,MAX(N43,L43*(1+Inputs!B11)/MAX(M43,1)),N43+(N43*O43-N43)*P43) | R43: =IF(Inputs!B7=1,L43*(1+Inputs!B11),M43*Q43) | S43: =R43/(1+Inputs!B11) | T43: =IF(Inputs!B7=1,L43,MIN(S43,L43)) | U43: =IF(Inputs!B19=1,MAX(0,T43-J43),0) | V43: =T43*(1+Inputs!B11) | W43: =V43-T43 | X43: =V43*Inputs!B13*MIN(12,Inputs!B10)/12 | Y43: =W43*Inputs!B14/12 | Z43: =J43+U43-T43+X43-Y43 | AA43: =D43+E43-I43+U43+X43-Y43 | AB43: =IF(U43>0,AB42*(1+Inputs!B15/12)+U43,AB42*(1+Inputs!B15/12)) | AC43: =IF(Inputs!B21>0,AA43/Inputs!B21,0) | AD43: =G43+T43 | AE43: =H43+W43 | AF43: =AD43+AE43 | AG43: =IF(M43>0,V43/M43,0) | AH43: =AH42+U43 | AI43: =IFERROR((1+IRR(VSTACK($AJ$8:INDEX($AJ:$AJ,ROW()-1),-U43+AA43)))^12-1,0) | AJ43: =-U43
...

Sheet Notes
A1: Model Notes
A2: Contact Reif Tauati · 4176197004 · reif@thegoodproject.net
A4: What is modeled? | B4: This workbook mirrors the deterministic monthly Fund One model from /model over 120 months.
A5: Capital calls | B5: If Capital Calls On = 1 and Hardcore Mode = 0, LP capital is called only when needed. If Hardcore Mode = 1, the workbook assumes the full fund is funded upfront and redeployed immediately as cash returns.
A6: Borrower Rate vs Fund Take | B6: Borrower Rate is what the developer pays. Fund Take is the retained APY inside the fund after origination partners are paid.
A7: Debt / Equity | B7: A value of 0.25 means each $1.00 of LP equity supports $1.25 of loans through $0.25 of debt.
A8: How origination scales | B8: Desired origination volume is driven by pipeline capacity and deployable capital. In normal mode the model ramps scaling over 12 months. Hardcore Mode removes that gentler ramp and pushes available cash out immediately.
A9: IRR | B9: Projected IRR is solved from LP cash calls and terminal NAV. The Monthly_Model sheet also includes an IRR To Date column.
